package com.nit.cj_exception_handling;

public class Finally_Block_With_Transfer_Stmt_Case4 {

	public static void main(String[] args) {
		
		m1();
		System.out.println("after m1 calling");

	}

	static void m1() {

	/**	try {
			System.out.println("In try");
			System.out.println(10/0);

		} catch (NullPointerException npe) {
			System.out.println("In catch");

		} finally {
			System.out.println("In finally");
			return;
		}

	*/	

	}

}
